Traceback (most recent call last):
  File "/home/felipe/miniconda3/lib/python3.7/site-packages/jupyter_cache/executors/utils.py", line 56, in single_nb_execution
    record_timing=False,
  File "/home/felipe/miniconda3/lib/python3.7/site-packages/nbclient/client.py", line 1082, in execute
    return NotebookClient(nb=nb, resources=resources, km=km, **kwargs).execute()
  File "/home/felipe/miniconda3/lib/python3.7/site-packages/nbclient/util.py", line 74, in wrapped
    return just_run(coro(*args, **kwargs))
  File "/home/felipe/miniconda3/lib/python3.7/site-packages/nbclient/util.py", line 53, in just_run
    return loop.run_until_complete(coro)
  File "/home/felipe/miniconda3/lib/python3.7/asyncio/base_events.py", line 583, in run_until_complete
    return future.result()
  File "/home/felipe/miniconda3/lib/python3.7/site-packages/nbclient/client.py", line 536, in async_execute
    cell, index, execution_count=self.code_cells_executed + 1
  File "/home/felipe/miniconda3/lib/python3.7/site-packages/nbclient/client.py", line 827, in async_execute_cell
    self._check_raise_for_error(cell, exec_reply)
  File "/home/felipe/miniconda3/lib/python3.7/site-packages/nbclient/client.py", line 735, in _check_raise_for_error
    raise CellExecutionError.from_cell_and_msg(cell, exec_reply['content'])
nbclient.exceptions.CellExecutionError: An error occurred while executing the following cell:
------------------
begin
	plot(sol,linewidth=5, title="Solución aproximada al problema",
     xaxis="Time (t)", yaxis="u(t) (in μm)",label="Aproximación")
	plot!(sol.t, t->0.5*exp(1.01t),lw=3,ls=:dash,label="Solución exacta")
end

------------------

UndefVarError: sol not defined

Stacktrace:
 [1] top-level scope at In[9]:2
 [2] include_string(::Function, ::Module, ::String, ::String) at ./loading.jl:1091
LoadError: UndefVarError: sol not defined

